[2021-10-29 22:27:10,280: INFO/MainProcess] Connected to amqp://guest:**@192.168.56.10:5672//
[2021-10-29 22:27:10,299: INFO/MainProcess] mingle: searching for neighbors
[2021-10-29 22:27:11,345: INFO/MainProcess] mingle: all alone
[2021-10-29 22:27:11,380: INFO/MainProcess] celery@worker1 ready.
[2021-10-29 22:27:21,566: INFO/MainProcess] Connected to amqp://guest:**@192.168.56.10:5672//
[2021-10-29 22:27:21,586: INFO/MainProcess] mingle: searching for neighbors
[2021-10-29 22:27:22,632: INFO/MainProcess] mingle: all alone
[2021-10-29 22:27:22,665: INFO/MainProcess] celery@worker1 ready.
[2021-10-29 22:27:25,402: INFO/MainProcess] Events of group {task} enabled by remote.
[2021-10-29 22:28:36,385: INFO/MainProcess] sync with celery@worker2
[2021-10-29 22:31:38,732: INFO/MainProcess] Task proj.tasks.ping_console[8937edfd-ebcf-4d16-aa35-c083a5abf351] received
[2021-10-29 22:31:38,735: INFO/ForkPoolWorker-1] proj.tasks.ping_console[8937edfd-ebcf-4d16-aa35-c083a5abf351]: try to ping servername:  10.0.0.0
[2021-10-29 22:31:39,771: INFO/ForkPoolWorker-1] Task proj.tasks.ping_console[8937edfd-ebcf-4d16-aa35-c083a5abf351] succeeded in 1.036522605999835s: True
[2021-10-29 22:31:39,801: INFO/MainProcess] Task proj.tasks.change_power[499e6772-c1f0-404a-a924-5c0c2a07ce4b] received
[2021-10-29 22:31:43,086: INFO/MainProcess] Task proj.tasks.ping_console[b0c9dabd-589e-4420-9621-e6113599a8a4] received
[2021-10-29 22:31:43,089: INFO/ForkPoolWorker-1] proj.tasks.ping_console[b0c9dabd-589e-4420-9621-e6113599a8a4]: try to ping servername:  10.0.0.0
[2021-10-29 22:31:43,388: INFO/MainProcess] Task proj.tasks.change_power[67fe89ae-918f-449e-b862-fed2596cf88f] received
[2021-10-29 22:31:47,175: INFO/ForkPoolWorker-1] Task proj.tasks.ping_console[b0c9dabd-589e-4420-9621-e6113599a8a4] succeeded in 4.0860765259999425s: True
[2021-10-29 22:31:47,181: INFO/MainProcess] Task proj.tasks.change_power[1fe3e270-7bf2-475e-a1b6-d5049aedbc3b] received
[2021-10-29 22:33:39,811: INFO/ForkPoolWorker-1] proj.tasks.change_power[499e6772-c1f0-404a-a924-5c0c2a07ce4b]: try to change powerstatus of server:  XXXXXXXXXXXXXXX
[2021-10-29 22:33:39,817: INFO/ForkPoolWorker-1] Task proj.tasks.change_power[499e6772-c1f0-404a-a924-5c0c2a07ce4b] retry: Retry in 120s: TypeError('exceptions must derive from BaseException')
[2021-10-29 22:33:43,818: INFO/ForkPoolWorker-1] proj.tasks.change_power[67fe89ae-918f-449e-b862-fed2596cf88f]: try to change powerstatus of server:  XXXXXXXXXXXXXXX
[2021-10-29 22:33:43,821: INFO/MainProcess] Task proj.tasks.change_power[67fe89ae-918f-449e-b862-fed2596cf88f] received
[2021-10-29 22:33:43,823: INFO/ForkPoolWorker-1] Task proj.tasks.change_power[67fe89ae-918f-449e-b862-fed2596cf88f] retry: Retry in 120s: TypeError('exceptions must derive from BaseException')
[2021-10-29 22:33:47,825: INFO/ForkPoolWorker-1] proj.tasks.change_power[1fe3e270-7bf2-475e-a1b6-d5049aedbc3b]: try to change powerstatus of server:  XXXXXXXXXXXXXXX
[2021-10-29 22:33:47,830: INFO/ForkPoolWorker-1] Task proj.tasks.change_power[1fe3e270-7bf2-475e-a1b6-d5049aedbc3b] retry: Retry in 120s: TypeError('exceptions must derive from BaseException')
[2021-10-29 22:35:40,010: INFO/MainProcess] Task proj.tasks.change_power[499e6772-c1f0-404a-a924-5c0c2a07ce4b] received
[2021-10-29 22:35:44,012: INFO/ForkPoolWorker-1] proj.tasks.change_power[67fe89ae-918f-449e-b862-fed2596cf88f]: try to change powerstatus of server:  XXXXXXXXXXXXXXX
[2021-10-29 22:35:44,016: INFO/ForkPoolWorker-1] Task proj.tasks.change_power[67fe89ae-918f-449e-b862-fed2596cf88f] retry: Retry in 120s: TypeError('exceptions must derive from BaseException')
[2021-10-29 22:35:48,018: INFO/MainProcess] Task proj.tasks.change_power[1fe3e270-7bf2-475e-a1b6-d5049aedbc3b] received
[2021-10-29 22:37:40,206: INFO/ForkPoolWorker-1] proj.tasks.change_power[499e6772-c1f0-404a-a924-5c0c2a07ce4b]: try to change powerstatus of server:  XXXXXXXXXXXXXXX
[2021-10-29 22:37:40,213: ERROR/ForkPoolWorker-1] Task proj.tasks.change_power[499e6772-c1f0-404a-a924-5c0c2a07ce4b] raised unexpected: TypeError('exceptions must derive from BaseException')
Traceback (most recent call last):
  File "/usr/local/lib/python3.7/dist-packages/celery/app/trace.py", line 450, in trace_task
    R = retval = fun(*args, **kwargs)
  File "/usr/local/lib/python3.7/dist-packages/celery/app/trace.py", line 731, in __protected_call__
    return self.run(*args, **kwargs)
  File "/usr/local/lib/python3.7/dist-packages/celery/app/autoretry.py", line 54, in run
    ret = task.retry(exc=exc, **retry_kwargs)
  File "/usr/local/lib/python3.7/dist-packages/celery/app/task.py", line 714, in retry
    raise_with_context(exc)
  File "/usr/local/lib/python3.7/dist-packages/celery/app/autoretry.py", line 34, in run
    return task._orig_run(*args, **kwargs)
  File "/vagrant/VMworker1/proj/tasks.py", line 23, in change_power
    raise self.retry(exc=exc)
  File "/usr/local/lib/python3.7/dist-packages/celery/app/task.py", line 714, in retry
    raise_with_context(exc)
  File "/vagrant/VMworker1/proj/tasks.py", line 21, in change_power
    raise "test retry"
TypeError: exceptions must derive from BaseException
[2021-10-29 22:37:48,216: INFO/ForkPoolWorker-1] proj.tasks.change_power[1fe3e270-7bf2-475e-a1b6-d5049aedbc3b]: try to change powerstatus of server:  XXXXXXXXXXXXXXX
[2021-10-29 22:37:48,222: ERROR/ForkPoolWorker-1] Task proj.tasks.change_power[1fe3e270-7bf2-475e-a1b6-d5049aedbc3b] raised unexpected: TypeError('exceptions must derive from BaseException')
Traceback (most recent call last):
  File "/usr/local/lib/python3.7/dist-packages/celery/app/trace.py", line 450, in trace_task
    R = retval = fun(*args, **kwargs)
  File "/usr/local/lib/python3.7/dist-packages/celery/app/trace.py", line 731, in __protected_call__
    return self.run(*args, **kwargs)
  File "/usr/local/lib/python3.7/dist-packages/celery/app/autoretry.py", line 54, in run
    ret = task.retry(exc=exc, **retry_kwargs)
  File "/usr/local/lib/python3.7/dist-packages/celery/app/task.py", line 714, in retry
    raise_with_context(exc)
  File "/usr/local/lib/python3.7/dist-packages/celery/app/autoretry.py", line 34, in run
    return task._orig_run(*args, **kwargs)
  File "/vagrant/VMworker1/proj/tasks.py", line 23, in change_power
    raise self.retry(exc=exc)
  File "/usr/local/lib/python3.7/dist-packages/celery/app/task.py", line 714, in retry
    raise_with_context(exc)
  File "/vagrant/VMworker1/proj/tasks.py", line 21, in change_power
    raise "test retry"
TypeError: exceptions must derive from BaseException
